<?xml version="1.0"?>
<robot name="my_box_robot" xmlns:xacro="http://ros.org/wiki/xacro">

  <!-- Materiales -->
  <material name="gray">
    <color rgba="0.5 0.5 0.5 1.0"/>
  </material>
  <material name="black">
    <color rgba="0.0 0.0 0.0 1.0"/>
  </material>
  <material name="blue">
    <color rgba="0.0 0.0 1.0 1.0"/>
  </material>
  <material name="white">
    <color rgba="1 1 1 1"/>
  </material>


  <!-- Base del robot (elevada) -->
  <link name="base_link">
    <visual>
      <origin xyz="0 0 0.15" rpy="0 0 0"/>
      <geometry>
        <box size="0.4 0.3 0.2"/>
      </geometry>
      <material name="gray"/>
    </visual>
    <collision>
      <origin xyz="0 0 0.15" rpy="0 0 0"/>
      <geometry>
        <box size="0.4 0.3 0.2"/>
      </geometry>
    </collision>
    <inertial>
      <mass value="5.0"/>
      <origin xyz="0 0 0.15" rpy="0 0 0"/>
      <inertia ixx="0.1" iyy="0.1" izz="0.1" ixy="0.0" ixz="0.0" iyz="0.0"/>
    </inertial>
  </link>

    <gazebo reference="base_link">
        <material>Gazebo/Red</material>
    </gazebo>

  <!-- Rueda izquierda -->
  <link name="left_wheel">
    <visual>
      <origin xyz="0 0 0" rpy="0 0 0"/>
      <geometry>
        <cylinder length="0.05" radius="0.05"/>
      </geometry>
      <material name="black"/>
    </visual>
    <collision>
      <origin xyz="0 0 0" rpy="0 0 0"/>
      <geometry>
        <cylinder length="0.05" radius="0.05"/>
      </geometry>
    </collision>
    <inertial>
      <mass value="0.2"/>
      <origin xyz="0 0 0" rpy="0 0 0"/>
      <inertia ixx="0.001" iyy="0.001" izz="0.001" ixy="0.0" ixz="0.0" iyz="0.0"/>
    </inertial>
  </link>
  
    <gazebo reference="left_wheel">
        <material>Gazebo/Black</material>
    </gazebo>

  <!-- Rueda derecha -->
  <link name="right_wheel">
    <visual>
      <origin xyz="0 0 0" rpy="0 0 0"/>
      <geometry>
        <cylinder length="0.05" radius="0.05"/>
      </geometry>
      <material name="black"/>
    </visual>
    <collision>
      <origin xyz="0 0 0" rpy="0 0 0"/>
      <geometry>
        <cylinder length="0.05" radius="0.05"/>
      </geometry>
    </collision>
    <inertial>
      <mass value="0.2"/>
      <origin xyz="0 0 0" rpy="0 0 0"/>
      <inertia ixx="0.001" iyy="0.001" izz="0.001" ixy="0.0" ixz="0.0" iyz="0.0"/>
    </inertial>
  </link>

  <gazebo reference="right_wheel">
    <material>Gazebo/Black</material>
  </gazebo>

  <!-- Rueda caster frontal -->
  <link name="caster_wheel">
    <visual>
      <origin xyz="0 0 0" rpy="0 0 0"/>
      <geometry>
        <sphere radius="0.03"/>
      </geometry>
      <material name="blue"/>
    </visual>
    <collision>
      <origin xyz="0 0 0" rpy="0 0 0"/>
      <geometry>
        <sphere radius="0.03"/>
      </geometry>
    </collision>
    <inertial>
      <mass value="0.1"/>
      <origin xyz="0 0 0" rpy="0 0 0"/>
      <inertia ixx="0.0001" iyy="0.0001" izz="0.0001" ixy="0.0" ixz="0.0" iyz="0.0"/>
    </inertial>
  </link>

  <gazebo reference="caster_wheel">
    <material>Gazebo/Blue</material>
  </gazebo>

  <!-- Articulación rueda izquierda -->
  <joint name="left_wheel_joint" type="continuous">
    <parent link="base_link"/>
    <child link="left_wheel"/>
    <origin xyz="-0.1 0.13 0.05" rpy="1.5708 0 0"/>
    <axis xyz="0 0 1"/>
    <limit effort="1.0" velocity="10.0"/>
    <dynamics damping="0.1"/>
  </joint>

  <!-- Articulación rueda derecha -->
  <joint name="right_wheel_joint" type="continuous">
    <parent link="base_link"/>
    <child link="right_wheel"/>
    <origin xyz="-0.1 -0.13 0.05" rpy="1.5708 0 0"/>
    <axis xyz="0 0 1"/>
    <limit effort="1.0" velocity="10.0"/>
    <dynamics damping="0.1"/>
  </joint>

  <!-- Articulación rueda caster -->
  <joint name="caster_wheel_joint" type="fixed">
    <parent link="base_link"/>
    <child link="caster_wheel"/>
    <origin xyz="0.18 0 0.03" rpy="0 0 0"/>
  </joint>


<link name="left_marker">
  <visual>
    <origin xyz="0.06 0 0" rpy="0 0 0"/>
    <geometry>
      <box size="0.1 0.01 0.01"/>
    </geometry>
    <material name="white"/>
  </visual>
</link>

<joint name="left_marker_joint" type="fixed">
  <parent link="left_wheel"/>
  <child link="left_marker"/>
  <origin xyz="0 0 0" rpy="0 0 0"/>
</joint>


<link name="right_marker">
  <visual>
    <origin xyz="0.06 0 0" rpy="0 0 0"/>
    <geometry>
      <box size="0.1 0.01 0.01"/>
    </geometry>
    <material name="white"/>
  </visual>
</link>

<joint name="right_marker_joint" type="fixed">
  <parent link="right_wheel"/>
  <child link="right_marker"/>
  <origin xyz="0 0 0" rpy="0 0 0"/>
</joint>


<link name="caster_marker">
  <visual>
    <origin xyz="0.06 0 0" rpy="0 0 0"/>
    <geometry>
      <box size="0.1 0.01 0.01"/>
    </geometry>
    <material name="white"/>
  </visual>
</link>

<joint name="caster_marker_joint" type="fixed">
  <parent link="caster_wheel"/>
  <child link="caster_marker"/>
  <origin xyz="0 0 0" rpy="0 0 0"/>
</joint>


  <gazebo>
  <plugin name="diff_drive_plugin" filename="libdiff_drive_plugin.so">
    <wheel_radius>0.05</wheel_radius>
    <wheel_separation>0.26</wheel_separation>
  </plugin>
</gazebo>


  <!-- Sensor LIDAR (Hokuyo simulado) -->
  <link name="lidar_link">
    <visual>
      <origin xyz="0 0 0" rpy="0 0 0"/>
      <geometry>
        <cylinder radius="0.03" length="0.05"/>
      </geometry>
      <material name="black"/>
    </visual>
    <collision>
      <origin xyz="0 0 0" rpy="0 0 0"/>
      <geometry>
        <cylinder radius="0.03" length="0.05"/>
      </geometry>
    </collision>
    <inertial>
      <mass value="0.1"/>
      <origin xyz="0 0 0" rpy="0 0 0"/>
      <inertia ixx="0.00001" iyy="0.00001" izz="0.00001" ixy="0" ixz="0" iyz="0"/>
    </inertial>
  </link>

  <joint name="lidar_joint" type="fixed">
    <parent link="base_link"/>
    <child link="lidar_link"/>
    <origin xyz="0 0 0.5" rpy="0 0 0"/>  <!-- Ajusta altura -->
  </joint>

  <gazebo reference="lidar_link">
    <sensor name="lidar_sensor" type="ray">
      <update_rate>10</update_rate>
      <pose>0 0 0 0 0 0</pose>
      <ray>
        <scan>
          <horizontal>
            <samples>720</samples>
            <resolution>1</resolution>
            <min_angle>-1.57</min_angle>
            <max_angle>1.57</max_angle>
          </horizontal>
        </scan>
        <range>
          <min>0.12</min>
          <max>3.5</max>
          <resolution>0.01</resolution>
        </range>
        <noise>
          <type>gaussian</type>
          <mean>0.0</mean>
          <stddev>0.01</stddev>
        </noise>
      </ray>
      <plugin name="gazebo_ros_laser_controller" filename="libgazebo_ros_ray_sensor.so">
        <ros>
          <remapping>~/out:=scan</remapping>
        </ros>
        <output_type>sensor_msgs/LaserScan</output_type>
        <frame_name>lidar_link</frame_name>
      </plugin>
    </sensor>
  </gazebo>


</robot>
